--- test_insert_at_pos
Traceback (most recent call last):
  File "test_util.py", line 263, in run_tests
    i()
  File "test_util.py", line 248, in test_insert_at_pos
    assertEquals(inserted, util.insert_at_pos('0', util.Pos(2, 9), testStr))
  File "test_util.py", line 18, in assertEquals
    fail('Expected {} but given {}'.format(a, b))
  File "test_util.py", line 13, in fail
    raise AssertionFailedException(msg)
AssertionFailedException: Expected for i in range(5):
        print(10)
        print(i) but given for i in range(5):
        0print(1)
        print(i)
--------------------
