EXCEPTION: Inside Exception Lang_17 would run forever with parallel
Traceback (most recent call last):
  File "run.py", line 19, in task
    raise Exception(f'{bug_id} would run forever with parallel')
Exception: Lang_17 would run forever with parallel

