--- test_parse_ending_point_3
Traceback (most recent call last):
  File "test_util.py", line 315, in run_tests
    i()
  File "test_util.py", line 186, in test_parse_ending_point_3
    assertEquals(util.Pos(71, 32), pos)
  File "test_util.py", line 18, in assertEquals
    fail('Expected {} but given {}'.format(a, b))
  File "test_util.py", line 13, in fail
    raise AssertionFailedException(msg)
AssertionFailedException: Expected Pos(71, 32) but given Pos(71, 27)
--------------------
